Workbook

Sheet Read me
A1: Dimensional Summoner — encounters, drops and chains
A2: Generated from src/dimensional_sim/world/catalog.py on 2026-10-16 (6 landmark sites, camp buildings; encounters-v11, save schema 13).
A4: How to use
A5: Blue text on yellow | B5: An input you can change: weights, region %, tier odds, drop odds, chances.
A6: Black text | B6: A formula. Every chance in this workbook recalculates from the inputs.
A7: Changing the game | B7: Edits here do not change the game. Send the file back and the changes get ported into catalog.py.
A9: How a spot is rolled
A10: 1. Spots per chunk | B10: Each new chunk rolls one entry of [0, 1, 1, 2, 2, 3] (average 1.5 spots).
A11: 2. Tier first | B11: Rare rolls first; a miss tries uncommon; common catches the rest. A tier with nothing eligible is skipped.
A12: 3. Tier odds scale | B12: Tier odds x (eligible weight in that tier / its full weight), capped at 90%. Unlocking more of a tier raises its odds.
A13: 4. Pick in tier | B13: Inside the tier, an encounter is picked by effective weight (base weight x region %, rounded down like the game).
A14: 5. After the roll | B14: At-once caps (windows), spawn pity and the Journal guarantee apply after this table; Journal favor/suppress is not modelled here.
A16: How loot works
A17: Fixed loot | B17: Each fixed entry rolls on its own (sheet 'Fixed loot'). These feed the auto-pilot's food and crafting plans.
A18: Bonus roll | B18: Actions with a drop table make ONE extra cascading roll (sheet 'Drop tables'); at most one item. Ring depth does not apply.
A20: Chains | B20: Completing an encounter can create a temporary lead next to it (sheet 'Chains'). Leads are not part of the spawn roll.
A21: Sites | B21: A site's own encounters are drawn from its bucket by base weight (region % does not apply), each at most once, on top of the wild spots.
A23: Sheets
A24: Encounters | B24: Every spot and lead: tier, weight, unlock, regions, caps, fight HP, drops.
A25: Spawn odds | B25: Chance per spot draw in each region, with an 'Unlocked' switch per encounter.
A26: Regions | B26: Region weight % per encounter (0 = never there).
A27: Tiers | B27: Tier odds and full weights for encounter spots.
A28: Fixed loot | B28: Guaranteed/independent drops per action.
A29: Drop tables | B29: Bonus-roll tables, tier odds, picks, and each item's exact chance per table.
A30: Bonus drops | B30: Each action's bonus items with chance and expected ash per completion.
A31: Chains | B31: Current chained encounters plus a blank table for chain ideas.
A32: Sites | B32: Landmark sites: where they can appear, how often, and their own encounters.
A33: Site encounters | B33: Inside each site: how likely each of its encounters is to show up in a life, and what it gives.
A34: Biomes & enemies | B34: Biomes, region layout (canopy, brush, which sites can appear) and enemy danger by ring.
A35: Crafts & buildings | B35: Every craft and building: where it can be made, cost, result, gate and bind cost.
... A39: Site conditions | B39: How a landmark is this life (quiet, already searched, untouched, a den, overgrown) and the rare phenomena.

Sheet Tiers
A1: Encounter tier odds
A2: Basis points in the catalog; shown here as %. The fallback tier (common) has no odds: it catches misses.
A4: Tier | B4: Spot odds | C4: Full weight | D4: Color | E4: Notes
A5: rare | B5: 0.06 | C5: 10 | D5: #7fb4ff | E5: No rare encounters exist yet: the tier is skipped.
A6: uncommon | B6: 0.25 | C6: 16 | D6: #8fd17a | E6: Full odds once this much uncommon weight is eligible here.
A7: common | B7: fallback | C7: - | D7: #e7d7b0
A9: Tier cap | B9: 0.9
A10: Ring (depth) | B10: 0 | C10: ring of the chunk being rolled
A11: Rarity per ring | B11: 0 | C11: dark_forest.spot_rarity_per_ring (0 = depth does not change odds)
A12: Ring multiplier | B12: =1+B11*B10 -> 1

Sheet Encounters
A1: Encounters
A2: Spots are rolled into chunks; leads only appear through a chain (see Chains); site encounters only inside their landmark (see Sites).
A4: ID | B4: Name | C4: Placement | D4: Category | E4: Tier | F4: Base weight | G4: Unlock (cost) | H4: Needs knowledge | I4: Allowed regions | J4: Next to | K4: At-once cap | L4: Enemy HP | M4: XP | N4: Duration (s) | O4: Heal | P4: Blessing | Q4: Bonus table | R4: Leads to | S4: Interaction (what you do) | T4: Depletes nearby
A5: bramble_berries | B5: Berry bush | C5: spot | D5: forage | E5: common | F5: 11 | G5: start | I5: all | K5: 1-2 | M5: 40 | N5: 2.4 | R5: trampled_bushes (15%) | S5: Picking berries | T5: berries
A6: fallen_branches | B6: Fallen branches | C6: spot | D6: gather | E6: common | F6: 18 | G6: start | I6: The Old Road, Deep Woods, Bramble Thicket | K6: no cap | M6: 30 | N6: 2.2 | R6: broken_branches (15%) | S6: Picking up sticks | T6: wood
A7: animal_tracks | B7: Animal tracks | C7: spot | D7: observe | E7: common | F7: 12 | G7: start | I7: Deep Woods, Still Glade | K7: no cap | M7: 50 | N7: 3 | R7: follow_deer_tracks (30%) | S7: Looking at the tracks | T7: game
A8: forest_spring | B8: Forest spring | C8: spot | D8: drink | E8: common | F8: 9 | G8: start | I8: all | K8: 1-2 | M8: 40 | N8: 2 | O8: 10 | R8: fresh_footprints (8%) | S8: Drinking water
A9: reed_bed | B9: Reeds | C9: spot | D9: forage | E9: common | F9: 7 | G9: start | I9: all | K9: 1-2 | M9: 35 | N9: 2.6 | R9: fish_scales (30%) | S9: Searching the reeds
A10: fishing_pool | B10: Fishing pool | C10: spot | D10: hunt | E10: common | F10: 9 | G10: start | I10: all | K10: 0-2 | M10: 45 | N10: 3.6 | R10: lurker_burrow (10%) | S10: Fishing | T10: fish
A11: river_shallows | B11: Shallows | C11: spot | D11: observe | E11: common | F11: 4 | G11: start | I11: all | K11: no cap | M11: 40 | N11: 2.4 | R11: ripples (35%) | S11: Looking into the water
A12: fishing_net | B12: Old fishing net | C12: spot | D12: scavenge | E12: uncommon | F12: 3 | G12: start | I12: all | K12: 0-1 | M12: 40 | N12: 3 | R12: float_line (35%) | S12: Untangling the net
A13: river_lurker | B13: River lurker | C13: spot | D13: fight | E13: common | F13: 3 | G13: start | I13: all | K13: 0-1 | L13: 2 | M13: 80 | N13: 0.001 | Q13: lurker_spoils | S13: Fighting the lurker
A14: bramble_boar | B14: Wild boar | C14: spot | D14: fight | E14: common | F14: 9 | G14: start | I14: all | K14: 1-2 | L14: 3 | M14: 100 | N14: 0.001 | Q14: boar_spoils | S14: Fighting the boar
A15: gnarled_tree | B15: Old tree | C15: spot | D15: climb | E15: common | F15: 10 | G15: Climbing (15 ash) | I15: all | J15: tree | K15: 1-1 | M15: 60 | N15: 3.2 | S15: Climbing for eggs | T15: eggs
A16: dead_tree | B16: Dead tree | C16: spot | D16: gather | E16: common | F16: 8 | G16: start | I16: all | J16: tree | K16: no cap | M16: 45 | N16: 3.6 | S16: Chopping the dead tree | T16: wood
A17: mushroom_ring | B17: Mushrooms | C17: spot | D17: forage | E17: common | F17: 8 | G17: Mushroom lore (45 ash) | I17: Deep Woods | K17: 1-1 | M17: 55 | N17: 3.2 | R17: mushroom_dust (20%) | S17: Picking mushrooms | T17: fungi
A18: mossy_stone | B18: Mossy rock | C18: spot | D18: meditate | E18: common | F18: 7 | G18: Meditation (30 ash) | I18: all | J18: rock | K18: no cap | M18: 60 | N18: 4 | R18: double_shadow (12%) | S18: Resting by the rock
A19: hanging_leaf | B19: Hanging leaf | C19: spot | D19: observe | E19: rare | F19: 3 | G19: start | I19: Deep Woods, Still Glade | K19: 0-1 | M19: 70 | N19: 3 | S19: Watching the leaf
A20: backward_ripple | B20: Backward ripple | C20: spot | D20: observe | E20: rare | F20: 3 | G20: start | I20: all | K20: 0-1 | M20: 70 | N20: 3 | S20: Watching the water
A21: moonlit_pool | B21: Clear pool | C21: spot | D21: drink | E21: uncommon | F21: 5 | G21: Meditation (30 ash) | I21: all | K21: 0-1 | M21: 45 | N21: 2.6 | O21: 12 | S21: Drinking water
A22: old_carvings | B22: Old carvings | C22: spot | D22: study | E22: uncommon | F22: 5 | G22: Road lore (70 ash) | I22: all | K22: no cap | M22: 80 | N22: 3.6 | R22: trail_marker (30%) | S22: Reading the carvings
A23: wayside_shrine | B23: Roadside shrine | C23: spot | D23: pray | E23: uncommon | F23: 6 | G23: Shrine path (3 blessing) | I23: The Old Road | K23: 1-1 | M23: 50 | N23: 3.6 | P23: 1 | S23: Praying at the shrine
A24: follow_deer_tracks | B24: Deer tracks | C24: lead | D24: observe | E24: common | F24: lead | G24: start | H24: deer_sign | I24: all | K24: no cap | M24: 35 | N24: 3.8 | R24: hunt_deer (55%) | S24: Following the tracks
A25: hunt_deer | B25: Deer | C25: lead | D25: hunt | E25: common | F25: lead | G25: start | H25: deer_sign | I25: all | K25: no cap | M25: 80 | N25: 5.5 | Q25: deer_spoils | S25: Hunting the deer
A26: broken_branches | B26: Broken branches | C26: lead | D26: observe | E26: common | F26: lead | G26: start | I26: all | K26: no cap | M26: 30 | N26: 2.6 | R26: cut_wood (55%) | S26: Looking at the broken branches
A27: cut_wood | B27: Cut wood | C27: lead | D27: gather | E27: common | F27: lead | G27: start | I27: all | K27: no cap | M27: 40 | N27: 3.4 | Q27: wood_stash | S27: Taking the wood
A28: trampled_bushes | B28: Trampled bushes | C28: lead | D28: observe | E28: common | F28: lead | G28: start | I28: all | K28: no cap | M28: 30 | N28: 2.4 | R28: feeding_ground (50%), angry_boar (25%) | S28: Looking at the marks
A29: feeding_ground | B29: Feeding ground | C29: lead | D29: forage | E29: common | F29: lead | G29: start | I29: all | K29: no cap | M29: 40 | N29: 3 | S29: Picking what is left
A30: angry_boar | B30: Angry boar | C30: lead | D30: fight | E30: common | F30: lead | G30: start | I30: all | K30: no cap | L30: 3 | M30: 100 | N30: 0.001 | Q30: boar_spoils | S30: Fighting the boar
A31: mushroom_dust | B31: Mushroom dust | C31: lead | D31: observe | E31: common | F31: lead | G31: start | I31: all | K31: no cap | M31: 35 | N31: 2.6 | R31: rotten_log (60%) | S31: Following the dust
A32: rotten_log | B32: Rotten log | C32: lead | D32: forage | E32: common | F32: lead | G32: start | I32: all | K32: no cap | M32: 45 | N32: 3.2 | Q32: rotten_log | S32: Picking mushrooms
A33: trail_marker | B33: Odd trail marker | C33: lead | D33: study | E33: common | F33: lead | G33: start | I33: all | K33: no cap | M33: 60 | N33: 3.4 | R33: looping_path (50%) | S33: Comparing the marks
A34: looping_path | B34: Looping path | C34: lead | D34: observe | E34: common | F34: lead | G34: start | I34: all | K34: no cap | M34: 80 | N34: 4 | S34: Walking the loop
A35: map_scrap | B35: Hand-drawn map | C35: lead | D35: study | E35: common | F35: lead | G35: start | I35: all | K35: no cap | M35: 40 | N35: 3 | R35: hidden_stash (60%) | S35: Reading the map
A36: hidden_stash | B36: Hidden stash | C36: lead | D36: scavenge | E36: common | F36: lead | G36: start | I36: all | K36: no cap | M36: 50 | N36: 3.6 | Q36: hidden_stash | S36: Digging up the stash
A37: fish_scales | B37: Fish scales | C37: lead | D37: observe | E37: common | F37: lead | G37: start | I37: all | K37: no cap | M37: 30 | N37: 2.2 | R37: busy_pool (50%), lurker_burrow (20%) | S37: Following the scales
A38: busy_pool | B38: Busy pool | C38: lead | D38: hunt | E38: common | F38: lead | G38: start | I38: all | K38: no cap | M38: 50 | N38: 3.4 | S38: Fishing
A39: ripples | B39: Ripples | C39: lead | D39: observe | E39: common | F39: lead | G39: start | I39: all | K39: no cap | M39: 35 | N39: 2.4 | R39: lurker_burrow (50%) | S39: Watching the ripples
A40: lurker_burrow | B40: River lurker | C40: lead | D40: fight | E40: common | F40: lead | G40: start | I40: all | K40: no cap | L40: 2 | M40: 80 | N40: 0.001 | Q40: lurker_spoils | S40: Fighting the lurker
A41: float_line | B41: Torn float line | C41: lead | D41: observe | E41: common | F41: lead | G41: start | I41: all | K41: no cap | M41: 35 | N41: 2.6 | R41: fishing_platform (60%) | S41: Following the line
...

Sheet Sites
A1: Landmark sites
A2: One candidate chunk per 3x3 block rolls once against these per-mille weights (by its region).
A4: Site | B4: Structure | C4: Min ring | D4: Encounters per life | E4: Chance · The Old Road | F4: Chance · Deep Woods | G4: Chance · Bramble Thicket | H4: Chance · Still Glade | I4: Its encounters
A5: Abandoned camp | B5: camp | C5: 2 | D5: 2-3 | E5: 0.35 | F5: 0.15 | G5: 0.15 | H5: 0.1 | I5: Old backpacks, Old campfire, Torn blanket
A6: Fallen watchtower | B6: tower | C6: 3 | D6: 2-4 | E6: 0.3 | F6: 0.15 | G6: 0 | H6: 0 | I6: Fallen stones, Broken stairs, Old weapon rack, Scratched warnings, Fallen guard
A7: Logging camp | B7: lumber | C7: 2 | D7: 2-3 | E7: 0.1 | F7: 0.2 | G7: 0 | H7: 0 | I7: Log pile, Tool shed, Fallen tree
A8: Hunter's cabin | B8: lodge | C8: 3 | D8: 2-3 | E8: 0 | F8: 0.15 | G8: 0.25 | H8: 0 | I8: Hide racks, Old traps, Antler wall
A9: Ruined shrine | B9: shrine | C9: 4 | D9: 2-3 | E9: 0 | F9: 0.1 | G9: 0 | H9: 0.25 | I9: Broken altar, Coin bowls, Carved pillars, Pale wisp
A10: Burial mound | B10: barrow | C10: 5 | D10: 2-3 | E10: 0.05 | F10: 0.1 | G10: 0.15 | H10: 0 | I10: Old grave, Stone circle, Bone pile, Restless bones
A12: Chance a block holds a site | E12: =SUM(E5:E10) -> 0.8 | F12: =SUM(F5:F10) -> 0.85 | G12: =SUM(G5:G10) -> 0.55 | H12: =SUM(H5:H10) -> 0.35
A13: Roughly one site per this many chunks | E13: =IF(E12=0,"-",9/E12) -> 11.25 | F13: =IF(F12=0,"-",9/F12) -> 10.588235 | G13: =IF(G12=0,"-",9/G12) -> 16.363636 | H13: =IF(H12=0,"-",9/H12) -> 25.714286

Sheet Site encounters
A1: Site encounters
A2: Each life a site draws 'Min-Max' of its encounters (count uniform), by weight, each at most once. Assumes all of them are unlocked; a locked one simply drops out of the draw.
A4: Abandoned camp | C4: Min | D4: 2 | E4: Max | F4: 3 | G4: structure: camp · min ring 2 · uncommon
A5: ID | B5: Name | C5: Weight (Encounters sheet) | D5: P(1st pick) | E5: P(2nd pick) | F5: P(3rd pick) | G5: P(4th pick) | H5: P(shows up in a life) | I5: Unlock | J5: Fixed loot | K5: Bonus table | L5: Other
A6: camp_packs | B6: Old backpacks | C6: =Encounters!F49 -> 10 | D6: =$C$6/SUM($C$6:$C$8) -> 0.4 | E6: =($C$7/SUM($C$6:$C$8))*($C$6/(SUM($C$6:$C$8)-$C$7))+($C$8/SUM($C$6:$C$8))*($C$6/(SUM($C$6:$C$8)-$C$8)) -> 0.34379085 | F6: =($C$7/SUM($C$6:$C$8))*($C$8/(SUM($C$6:$C$8)-$C$7))*($C$6/(SUM($C$6:$C$8)-$C$7-$C$8))+($C$8/SUM($C$6:$C$8))*($C$7/(SUM($C$6:$C$8)-$C$8))*($C$6/(SUM($C$6:$C$8)-$C$8-$C$7)) -> 0.25620915 | G6: =0 -> 0 | H6: =MIN(1,(IF(AND(0>=$D$4,0<=$F$4),0,0)+IF(AND(1>=$D$4,1<=$F$4),D6,0)+IF(AND(2>=$D$4,2<=$F$4),D6+E6,0)+IF(AND(3>=$D$4,3<=$F$4),D6+E6+F6,0)+IF(AND(4>=$D$4,4<=$F$4),D6+E6+F6+G6,0)+IF(AND(5>=$D$4,5<=$F$4),D6+E6+F6+G6,0)+IF(AND(6>=$D$4,6<=$F$4),D6+E6+F6+G6,0)+IF(AND(7>=$D$4,7<=$F$4),D6+E6+F6+G6,0)+IF(AND(8>=$D$4,8<=$F$4),D6+E6+F6+G6,0))/($F$4-$D$4+1)) -> 0.87189542 | I6: Scavenging (20 ash) | J6: Stick 1-2, Cloth scrap 1-2 (70%) | K6: traveller_cache | L6: scavenge · strength 40 XP · 3.1s
A7: camp_firepit | B7: Old campfire | C7: =Encounters!F50 -> 8 | D7: =$C$7/SUM($C$6:$C$8) -> 0.32 | E7: =($C$6/SUM($C$6:$C$8))*($C$7/(SUM($C$6:$C$8)-$C$6))+($C$8/SUM($C$6:$C$8))*($C$7/(SUM($C$6:$C$8)-$C$8)) -> 0.33777778 | F7: =($C$6/SUM($C$6:$C$8))*($C$8/(SUM($C$6:$C$8)-$C$6))*($C$7/(SUM($C$6:$C$8)-$C$6-$C$8))+($C$8/SUM($C$6:$C$8))*($C$6/(SUM($C$6:$C$8)-$C$8))*($C$7/(SUM($C$6:$C$8)-$C$8-$C$6)) -> 0.34222222 | G7: =0 -> 0 | H7: =MIN(1,(IF(AND(0>=$D$4,0<=$F$4),0,0)+IF(AND(1>=$D$4,1<=$F$4),D7,0)+IF(AND(2>=$D$4,2<=$F$4),D7+E7,0)+IF(AND(3>=$D$4,3<=$F$4),D7+E7+F7,0)+IF(AND(4>=$D$4,4<=$F$4),D7+E7+F7+G7,0)+IF(AND(5>=$D$4,5<=$F$4),D7+E7+F7+G7,0)+IF(AND(6>=$D$4,6<=$F$4),D7+E7+F7+G7,0)+IF(AND(7>=$D$4,7<=$F$4),D7+E7+F7+G7,0)+IF(AND(8>=$D$4,8<=$F$4),D7+E7+F7+G7,0))/($F$4-$D$4+1)) -> 0.82888889 | I7: Scavenging (20 ash) | J7: Coil of rope 1-1 (60%), Bramble thorn 1-1 (40%) | L7: scavenge · perception 35 XP · 2.6s
A8: camp_bedroll | B8: Torn blanket | C8: =Encounters!F51 -> 7 | D8: =$C$8/SUM($C$6:$C$8) -> 0.28 | E8: =($C$6/SUM($C$6:$C$8))*($C$8/(SUM($C$6:$C$8)-$C$6))+($C$7/SUM($C$6:$C$8))*($C$8/(SUM($C$6:$C$8)-$C$7)) -> 0.31843137 | F8: =($C$6/SUM($C$6:$C$8))*($C$7/(SUM($C$6:$C$8)-$C$6))*($C$8/(SUM($C$6:$C$8)-$C$6-$C$7))+($C$7/SUM($C$6:$C$8))*($C$6/(SUM($C$6:$C$8)-$C$7))*($C$8/(SUM($C$6:$C$8)-$C$7-$C$6)) -> 0.40156863 | G8: =0 -> 0 | H8: =MIN(1,(IF(AND(0>=$D$4,0<=$F$4),0,0)+IF(AND(1>=$D$4,1<=$F$4),D8,0)+IF(AND(2>=$D$4,2<=$F$4),D8+E8,0)+IF(AND(3>=$D$4,3<=$F$4),D8+E8+F8,0)+IF(AND(4>=$D$4,4<=$F$4),D8+E8+F8+G8,0)+IF(AND(5>=$D$4,5<=$F$4),D8+E8+F8+G8,0)+IF(AND(6>=$D$4,6<=$F$4),D8+E8+F8+G8,0)+IF(AND(7>=$D$4,7<=$F$4),D8+E8+F8+G8,0)+IF(AND(8>=$D$4,8<=$F$4),D8+E8+F8+G8,0))/($F$4-$D$4+1)) -> 0.79921569 | I8: Scavenging (20 ash) | J8: Cloth scrap 1-3 | L8: teaches padded_jerkin · scavenge · endurance 35 XP · 2.8s
B9: Check: picks per life | H9: =SUM(H6:H8) -> 2.5
A11: Fallen watchtower | C11: Min | D11: 2 | E11: Max | F11: 4 | G11: structure: tower · min ring 3 · uncommon
A12: ID | B12: Name | C12: Weight (Encounters sheet) | D12: P(1st pick) | E12: P(2nd pick) | F12: P(3rd pick) | G12: P(4th pick) | H12: P(shows up in a life) | I12: Unlock | J12: Fixed loot | K12: Bonus table | L12: Other
A13: tower_rubble | B13: Fallen stones | C13: =Encounters!F52 -> 10 | D13: =$C$13/SUM($C$13:$C$17) -> 0.3125 | E13: =($C$14/SUM($C$13:$C$17))*($C$13/(SUM($C$13:$C$17)-$C$14))+($C$15/SUM($C$13:$C$17))*($C$13/(SUM($C$13:$C$17)-$C$15))+($C$16/SUM($C$13:$C$17))*($C$13/(SUM($C$13:$C$17)-$C$16))+($C$17/SUM($C$13:$C$17))*($C$13/(SUM($C$13:$C$17)-$C$17)) -> 0.25997151 | F13: =($C$14/SUM($C$13:$C$17))*($C$15/(SUM($C$13:$C$17)-$C$14))*($C$13/(SUM($C$13:$C$17)-$C$14-$C$15))+($C$14/SUM($C$13:$C$17))*($C$16/(SUM($C$13:$C$17)-$C$14))*($C$13/(SUM($C$13:$C$17)-$C$14-$C$16))+($C$14/SUM($C$13:$C$17))*($C$17/(SUM($C$13:$C$17)-$C$14))*($C$13/(SUM($C$13:$C$17)-$C$14-$C$17))+($C$15/SUM($C$13:$C$17))*($C$14/(SUM($C$13:$C$17)-$C$15))*($C$13/(SUM($C$13:$C$17)-$C$15-$C$14))+($C$15/SUM($C$13:$C$17))*($C$16/(SUM($C$13:$C$17)-$C$15))*($C$13/(SUM($C$13:$C$17)-$C$15-$C$16))+($C$15/SUM($C$13:$C$17))*($C$17/(SUM($C$13:$C$17)-$C$15))*($C$13/(SUM($C$13:$C$17)-$C$15-$C$17))+($C$16/SUM($C$13:$C$17))*($C$14/(SUM($C$13:$C$17)-$C$16))*($C$13/(SUM($C$13:$C$17)-$C$16-$C$14))+($C$16/SUM($C$13:$C$17))*($C$15/(SUM($C$13:$C$17)-$C$16))*($C$13/(SUM($C$13:$C$17)-$C$16-$C$15))+($C$16/SUM($C$13:$C$17))*($C$17/(SUM($C$13:$C$17)-$C$16))*($C$13/(SUM($C$13:$C$17)-$C$16-$C$17))+($C$17/SUM($C$13:$C$17))*($C$14/(SUM($C$13:$C$17)-$C$17))*($C$13/(SUM($C$13:$C$17)-$C$17-$C$14))+($C$17/SUM($C$13:$C$17))*($C$15/(SUM($C$13:$C$17)-$C$17))*($C$13/(SUM($C$13:$C$17)-$C$17-$C$15))+($C$17/SUM($C$13:$C$17))*($C$16/(SUM($C$13:$C$17)-$C$17))*($C$13/(SUM($C$13:$C$17)-$C$17-$C$16)) -> 0.20439283 | G13: =($C$14/SUM($C$13:$C$17))*($C$15/(SUM($C$13:$C$17)-$C$14))*($C$16/(SUM($C$13:$C$17)-$C$14-$C$15))*($C$13/(SUM($C$13:$C$17)-$C$14-$C$15-$C$16))+($C$14/SUM($C$13:$C$17))*($C$15/(SUM($C$13:$C$17)-$C$14))*($C$17/(SUM($C$13:$C$17)-$C$14-$C$15))*($C$13/(SUM($C$13:$C$17)-$C$14-$C$15-$C$17))+($C$14/SUM($C$13:$C$17))*($C$16/(SUM($C$13:$C$17)-$C$14))*($C$15/(SUM($C$13:$C$17)-$C$14-$C$16))*($C$13/(SUM($C$13:$C$17)-$C$14-$C$16-$C$15))+($C$14/SUM($C$13:$C$17))*($C$16/(SUM($C$13:$C$17)-$C$14))*($C$17/(SUM($C$13:$C$17)-$C$14-$C$16))*($C$13/(SUM($C$13:$C$17)-$C$14-$C$16-$C$17))+($C$14/SUM($C$13:$C$17))*($C$17/(SUM($C$13:$C$17)-$C$14))*($C$15/(SUM($C$13:$C$17)-$C$14-$C$17))*($C$13/(SUM($C$13:$C$17)-$C$14-$C$17-$C$15))+($C$14/SUM($C$13:$C$17))*($C$17/(SUM($C$13:$C$17)-$C$14))*($C$16/(SUM($C$13:$C$17)-$C$14-$C$17))*($C$13/(SUM($C$13:$C$17)-$C$14-$C$17-$C$16))+($C$15/SUM($C$13:$C$17))*($C$14/(SUM($C$13:$C$17)-$C$15))*($C$16/(SUM($C$13:$C$17)-$C$15-$C$14))*($C$13/(SUM($C$13:$C$17)-$C$15-$C$14-$C$16))+($C$15/SUM($C$13:$C$17))*($C$14/(SUM($C$13:$C$17)-$C$15))*($C$17/(SUM($C$13:$C$17)-$C$15-$C$14))*($C$13/(SUM($C$13:$C$17)-$C$15-$C$14-$C$17))+($C$15/SUM($C$13:$C$17))*($C$16/(SUM($C$13:$C$17)-$C$15))*($C$14/(SUM($C$13:$C$17)-$C$15-$C$16))*($C$13/(SUM($C$13:$C$17)-$C$15-$C$16-$C$14))+($C$15/SUM($C$13:$C$17))*($C$16/(SUM($C$13:$C$17)-$C$15))*($C$17/(SUM($C$13:$C$17)-$C$15-$C$16))*($C$13/(SUM($C$13:$C$17)-$C$15-$C$16-$C$17))+($C$15/SUM($C$13:$C$17))*($C$17/(SUM($C$13:$C$17)-$C$15))*($C$14/(SUM($C$13:$C$17)-$C$15-$C$17))*($C$13/(SUM($C$13:$C$17)-$C$15-$C$17-$C$14))+($C$15/SUM($C$13:$C$17))*($C$17/(SUM($C$13:$C$17)-$C$15))*($C$16/(SUM($C$13:$C$17)-$C$15-$C$17))*($C$13/(SUM($C$13:$C$17)-$C$15-$C$17-$C$16))+($C$16/SUM($C$13:$C$17))*($C$14/(SUM($C$13:$C$17)-$C$16))*($C$15/(SUM($C$13:$C$17)-$C$16-$C$14))*($C$13/(SUM($C$13:$C$17)-$C$16-$C$14-$C$15))+($C$16/SUM($C$13:$C$17))*($C$14/(SUM($C$13:$C$17)-$C$16))*($C$17/(SUM($C$13:$C$17)-$C$16-$C$14))*($C$13/(SUM($C$13:$C$17)-$C$16-$C$14-$C$17))+($C$16/SUM($C$13:$C$17))*($C$15/(SUM($C$13:$C$17)-$C$16))*($C$14/(SUM($C$13:$C$17)-$C$16-$C$15))*($C$13/(SUM($C$13:$C$17)-$C$16-$C$15-$C$14))+($C$16/SUM($C$13:$C$17))*($C$15/(SUM($C$13:$C$17)-$C$16))*($C$17/(SUM($C$13:$C$17)-$C$16-$C$15))*($C$13/(SUM($C$13:$C$17)-$C$16-$C$15-$C$17))+($C$16/SUM($C$13:$C$17))*($C$17/(SUM($C$13:$C$17)-$C$16))*($C$14/(SUM($C$13:$C$17)-$C$16-$C$17))*($C$13/(SUM($C$13:$C$17)-$C$16-$C$17-$C$14))+($C$16/SUM($C$13:$C$17))*($C$17/(SUM($C$13:$C$17)-$C$16))*($C$15/(SUM($C$13:$C$17)-$C$16-$C$17))*($C$13/(SUM($C$13:$C$17)-$C$16-$C$17-$C$15))+($C$17/SUM($C$13:$C$17))*($C$14/(SUM($C$13:$C$17)-$C$17))*($C$15/(SUM($C$13:$C$17)-$C$17-$C$14))*($C$13/(SUM($C$13:$C$17)-$C$17-$C$14-$C$15))+($C$17/SUM($C$13:$C$17))*($C$14/(SUM($C$13:$C$17)-$C$17))*($C$16/(SUM($C$13:$C$17)-$C$17-$C$14))*($C$13/(SUM($C$13:$C$17)-$C$17-$C$14-$C$16))+($C$17/SUM($C$13:$C$17))*($C$15/(SUM($C$13:$C$17)-$C$17))*($C$14/(SUM($C$13:$C$17)-$C$17-$C$15))*($C$13/(SUM($C$13:$C$17)-$C$17-$C$15-$C$14))+($C$17/SUM($C$13:$C$17))*($C$15/(SUM($C$13:$C$17)-$C$17))*($C$16/(SUM($C$13:$C$17)-$C$17-$C$15))*($C$13/(SUM($C$13:$C$17)-$C$17-$C$15-$C$16))+($C$17/SUM($C$13:$C$17))*($C$16/(SUM($C$13:$C$17)-$C$17))*($C$14/(SUM($C$13:$C$17)-$C$17-$C$16))*($C$13/(SUM($C$13:$C$17)-$C$17-$C$16-$C$14))+($C$17/SUM($C$13:$C$17))*($C$16/(SUM($C$13:$C$17)-$C$17))*($C$15/(SUM($C$13:$C$17)-$C$17-$C$16))*($C$13/(SUM($C$13:$C$17)-$C$17-$C$16-$C$15)) -> 0.14463314 | H13: =MIN(1,(IF(AND(0>=$D$11,0<=$F$11),0,0)+IF(AND(1>=$D$11,1<=$F$11),D13,0)+IF(AND(2>=$D$11,2<=$F$11),D13+E13,0)+IF(AND(3>=$D$11,3<=$F$11),D13+E13+F13,0)+IF(AND(4>=$D$11,4<=$F$11),D13+E13+F13+G13,0)+IF(AND(5>=$D$11,5<=$F$11),D13+E13+F13+G13,0)+IF(AND(6>=$D$11,6<=$F$11),D13+E13+F13+G13,0)+IF(AND(7>=$D$11,7<=$F$11),D13+E13+F13+G13,0)+IF(AND(8>=$D$11,8<=$F$11),D13+E13+F13+G13,0))/($F$11-$D$11+1)) -> 0.75694444 | I13: Road lore (70 ash) | J13: Iron nails 1-2 (80%), Stick 1-1 | K13: traveller_cache | L13: scavenge · strength 45 XP · 3.4s
A14: tower_stair | B14: Broken stairs | C14: =Encounters!F53 -> 6 | D14: =$C$14/SUM($C$13:$C$17) -> 0.1875 | E14: =($C$13/SUM($C$13:$C$17))*($C$14/(SUM($C$13:$C$17)-$C$13))+($C$15/SUM($C$13:$C$17))*($C$14/(SUM($C$13:$C$17)-$C$15))+($C$16/SUM($C$13:$C$17))*($C$14/(SUM($C$13:$C$17)-$C$16))+($C$17/SUM($C$13:$C$17))*($C$14/(SUM($C$13:$C$17)-$C$17)) -> 0.19794095 | F14: =($C$13/SUM($C$13:$C$17))*($C$15/(SUM($C$13:$C$17)-$C$13))*($C$14/(SUM($C$13:$C$17)-$C$13-$C$15))+($C$13/SUM($C$13:$C$17))*($C$16/(SUM($C$13:$C$17)-$C$13))*($C$14/(SUM($C$13:$C$17)-$C$13-$C$16))+($C$13/SUM($C$13:$C$17))*($C$17/(SUM($C$13:$C$17)-$C$13))*($C$14/(SUM($C$13:$C$17)-$C$13-$C$17))+($C$15/SUM($C$13:$C$17))*($C$13/(SUM($C$13:$C$17)-$C$15))*($C$14/(SUM($C$13:$C$17)-$C$15-$C$13))+($C$15/SUM($C$13:$C$17))*($C$16/(SUM($C$13:$C$17)-$C$15))*($C$14/(SUM($C$13:$C$17)-$C$15-$C$16))+($C$15/SUM($C$13:$C$17))*($C$17/(SUM($C$13:$C$17)-$C$15))*($C$14/(SUM($C$13:$C$17)-$C$15-$C$17))+($C$16/SUM($C$13:$C$17))*($C$13/(SUM($C$13:$C$17)-$C$16))*($C$14/(SUM($C$13:$C$17)-$C$16-$C$13))+($C$16/SUM($C$13:$C$17))*($C$15/(SUM($C$13:$C$17)-$C$16))*($C$14/(SUM($C$13:$C$17)-$C$16-$C$15))+($C$16/SUM($C$13:$C$17))*($C$17/(SUM($C$13:$C$17)-$C$16))*($C$14/(SUM($C$13:$C$17)-$C$16-$C$17))+($C$17/SUM($C$13:$C$17))*($C$13/(SUM($C$13:$C$17)-$C$17))*($C$14/(SUM($C$13:$C$17)-$C$17-$C$13))+($C$17/SUM($C$13:$C$17))*($C$15/(SUM($C$13:$C$17)-$C$17))*($C$14/(SUM($C$13:$C$17)-$C$17-$C$15))+($C$17/SUM($C$13:$C$17))*($C$16/(SUM($C$13:$C$17)-$C$17))*($C$14/(SUM($C$13:$C$17)-$C$17-$C$16)) -> 0.20621535 | G14: =($C$13/SUM($C$13:$C$17))*($C$15/(SUM($C$13:$C$17)-$C$13))*($C$16/(SUM($C$13:$C$17)-$C$13-$C$15))*($C$14/(SUM($C$13:$C$17)-$C$13-$C$15-$C$16))+($C$13/SUM($C$13:$C$17))*($C$15/(SUM($C$13:$C$17)-$C$13))*($C$17/(SUM($C$13:$C$17)-$C$13-$C$15))*($C$14/(SUM($C$13:$C$17)-$C$13-$C$15-$C$17))+($C$13/SUM($C$13:$C$17))*($C$16/(SUM($C$13:$C$17)-$C$13))*($C$15/(SUM($C$13:$C$17)-$C$13-$C$16))*($C$14/(SUM($C$13:$C$17)-$C$13-$C$16-$C$15))+($C$13/SUM($C$13:$C$17))*($C$16/(SUM($C$13:$C$17)-$C$13))*($C$17/(SUM($C$13:$C$17)-$C$13-$C$16))*($C$14/(SUM($C$13:$C$17)-$C$13-$C$16-$C$17))+($C$13/SUM($C$13:$C$17))*($C$17/(SUM($C$13:$C$17)-$C$13))*($C$15/(SUM($C$13:$C$17)-$C$13-$C$17))*($C$14/(SUM($C$13:$C$17)-$C$13-$C$17-$C$15))+($C$13/SUM($C$13:$C$17))*($C$17/(SUM($C$13:$C$17)-$C$13))*($C$16/(SUM($C$13:$C$17)-$C$13-$C$17))*($C$14/(SUM($C$13:$C$17)-$C$13-$C$17-$C$16))+($C$15/SUM($C$13:$C$17))*($C$13/(SUM($C$13:$C$17)-$C$15))*($C$16/(SUM($C$13:$C$17)-$C$15-$C$13))*($C$14/(SUM($C$13:$C$17)-$C$15-$C$13-$C$16))+($C$15/SUM($C$13:$C$17))*($C$13/(SUM($C$13:$C$17)-$C$15))*($C$17/(SUM($C$13:$C$17)-$C$15-$C$13))*($C$14/(SUM($C$13:$C$17)-$C$15-$C$13-$C$17))+($C$15/SUM($C$13:$C$17))*($C$16/(SUM($C$13:$C$17)-$C$15))*($C$13/(SUM($C$13:$C$17)-$C$15-$C$16))*($C$14/(SUM($C$13:$C$17)-$C$15-$C$16-$C$13))+($C$15/SUM($C$13:$C$17))*($C$16/(SUM($C$13:$C$17)-$C$15))*($C$17/(SUM($C$13:$C$17)-$C$15-$C$16))*($C$14/(SUM($C$13:$C$17)-$C$15-$C$16-$C$17))+($C$15/SUM($C$13:$C$17))*($C$17/(SUM($C$13:$C$17)-$C$15))*($C$13/(SUM($C$13:$C$17)-$C$15-$C$17))*($C$14/(SUM($C$13:$C$17)-$C$15-$C$17-$C$13))+($C$15/SUM($C$13:$C$17))*($C$17/(SUM($C$13:$C$17)-$C$15))*($C$16/(SUM($C$13:$C$17)-$C$15-$C$17))*($C$14/(SUM($C$13:$C$17)-$C$15-$C$17-$C$16))+($C$16/SUM($C$13:$C$17))*($C$13/(SUM($C$13:$C$17)-$C$16))*($C$15/(SUM($C$13:$C$17)-$C$16-$C$13))*($C$14/(SUM($C$13:$C$17)-$C$16-$C$13-$C$15))+($C$16/SUM($C$13:$C$17))*($C$13/(SUM($C$13:$C$17)-$C$16))*($C$17/(SUM($C$13:$C$17)-$C$16-$C$13))*($C$14/(SUM($C$13:$C$17)-$C$16-$C$13-$C$17))+($C$16/SUM($C$13:$C$17))*($C$15/(SUM($C$13:$C$17)-$C$16))*($C$13/(SUM($C$13:$C$17)-$C$16-$C$15))*($C$14/(SUM($C$13:$C$17)-$C$16-$C$15-$C$13))+($C$16/SUM($C$13:$C$17))*($C$15/(SUM($C$13:$C$17)-$C$16))*($C$17/(SUM($C$13:$C$17)-$C$16-$C$15))*($C$14/(SUM($C$13:$C$17)-$C$16-$C$15-$C$17))+($C$16/SUM($C$13:$C$17))*($C$17/(SUM($C$13:$C$17)-$C$16))*($C$13/(SUM($C$13:$C$17)-$C$16-$C$17))*($C$14/(SUM($C$13:$C$17)-$C$16-$C$17-$C$13))+($C$16/SUM($C$13:$C$17))*($C$17/(SUM($C$13:$C$17)-$C$16))*($C$15/(SUM($C$13:$C$17)-$C$16-$C$17))*($C$14/(SUM($C$13:$C$17)-$C$16-$C$17-$C$15))+($C$17/SUM($C$13:$C$17))*($C$13/(SUM($C$13:$C$17)-$C$17))*($C$15/(SUM($C$13:$C$17)-$C$17-$C$13))*($C$14/(SUM($C$13:$C$17)-$C$17-$C$13-$C$15))+($C$17/SUM($C$13:$C$17))*($C$13/(SUM($C$13:$C$17)-$C$17))*($C$16/(SUM($C$13:$C$17)-$C$17-$C$13))*($C$14/(SUM($C$13:$C$17)-$C$17-$C$13-$C$16))+($C$17/SUM($C$13:$C$17))*($C$15/(SUM($C$13:$C$17)-$C$17))*($C$13/(SUM($C$13:$C$17)-$C$17-$C$15))*($C$14/(SUM($C$13:$C$17)-$C$17-$C$15-$C$13))+($C$17/SUM($C$13:$C$17))*($C$15/(SUM($C$13:$C$17)-$C$17))*($C$16/(SUM($C$13:$C$17)-$C$17-$C$15))*($C$14/(SUM($C$13:$C$17)-$C$17-$C$15-$C$16))+($C$17/SUM($C$13:$C$17))*($C$16/(SUM($C$13:$C$17)-$C$17))*($C$13/(SUM($C$13:$C$17)-$C$17-$C$16))*($C$14/(SUM($C$13:$C$17)-$C$17-$C$16-$C$13))+($C$17/SUM($C$13:$C$17))*($C$16/(SUM($C$13:$C$17)-$C$17))*($C$15/(SUM($C$13:$C$17)-$C$17-$C$16))*($C$14/(SUM($C$13:$C$17)-$C$17-$C$16-$C$15)) -> 0.20965554 | H14: =MIN(1,(IF(AND(0>=$D$11,0<=$F$11),0,0)+IF(AND(1>=$D$11,1<=$F$11),D14,0)+IF(AND(2>=$D$11,2<=$F$11),D14+E14,0)+IF(AND(3>=$D$11,3<=$F$11),D14+E14+F14,0)+IF(AND(4>=$D$11,4<=$F$11),D14+E14+F14+G14,0)+IF(AND(5>=$D$11,5<=$F$11),D14+E14+F14+G14,0)+IF(AND(6>=$D$11,6<=$F$11),D14+E14+F14+G14,0)+IF(AND(7>=$D$11,7<=$F$11),D14+E14+F14+G14,0)+IF(AND(8>=$D$11,8<=$F$11),D14+E14+F14+G14,0))/($F$11-$D$11+1)) -> 0.59280303 | I14: Road lore (70 ash) | J14: Bird egg 1-1 (50%) | L14: climb · agility 60 XP · 3.6s
A15: tower_armory | B15: Old weapon rack | C15: =Encounters!F54 -> 5 | D15: =$C$15/SUM($C$13:$C$17) -> 0.15625 | E15: =($C$13/SUM($C$13:$C$17))*($C$15/(SUM($C$13:$C$17)-$C$13))+($C$14/SUM($C$13:$C$17))*($C$15/(SUM($C$13:$C$17)-$C$14))+($C$16/SUM($C$13:$C$17))*($C$15/(SUM($C$13:$C$17)-$C$16))+($C$17/SUM($C$13:$C$17))*($C$15/(SUM($C$13:$C$17)-$C$17)) -> 0.1720733 | F15: =($C$13/SUM($C$13:$C$17))*($C$14/(SUM($C$13:$C$17)-$C$13))*($C$15/(SUM($C$13:$C$17)-$C$13-$C$14))+($C$13/SUM($C$13:$C$17))*($C$16/(SUM($C$13:$C$17)-$C$13))*($C$15/(SUM($C$13:$C$17)-$C$13-$C$16))+($C$13/SUM($C$13:$C$17))*($C$17/(SUM($C$13:$C$17)-$C$13))*($C$15/(SUM($C$13:$C$17)-$C$13-$C$17))+($C$14/SUM($C$13:$C$17))*($C$13/(SUM($C$13:$C$17)-$C$14))*($C$15/(SUM($C$13:$C$17)-$C$14-$C$13))+($C$14/SUM($C$13:$C$17))*($C$16/(SUM($C$13:$C$17)-$C$14))*($C$15/(SUM($C$13:$C$17)-$C$14-$C$16))+($C$14/SUM($C$13:$C$17))*($C$17/(SUM($C$13:$C$17)-$C$14))*($C$15/(SUM($C$13:$C$17)-$C$14-$C$17))+($C$16/SUM($C$13:$C$17))*($C$13/(SUM($C$13:$C$17)-$C$16))*($C$15/(SUM($C$13:$C$17)-$C$16-$C$13))+($C$16/SUM($C$13:$C$17))*($C$14/(SUM($C$13:$C$17)-$C$16))*($C$15/(SUM($C$13:$C$17)-$C$16-$C$14))+($C$16/SUM($C$13:$C$17))*($C$17/(SUM($C$13:$C$17)-$C$16))*($C$15/(SUM($C$13:$C$17)-$C$16-$C$17))+($C$17/SUM($C$13:$C$17))*($C$13/(SUM($C$13:$C$17)-$C$17))*($C$15/(SUM($C$13:$C$17)-$C$17-$C$13))+($C$17/SUM($C$13:$C$17))*($C$14/(SUM($C$13:$C$17)-$C$17))*($C$15/(SUM($C$13:$C$17)-$C$17-$C$14))+($C$17/SUM($C$13:$C$17))*($C$16/(SUM($C$13:$C$17)-$C$17))*($C$15/(SUM($C$13:$C$17)-$C$17-$C$16)) -> 0.19158823 | G15: =($C$13/SUM($C$13:$C$17))*($C$14/(SUM($C$13:$C$17)-$C$13))*($C$16/(SUM($C$13:$C$17)-$C$13-$C$14))*($C$15/(SUM($C$13:$C$17)-$C$13-$C$14-$C$16))+($C$13/SUM($C$13:$C$17))*($C$14/(SUM($C$13:$C$17)-$C$13))*($C$17/(SUM($C$13:$C$17)-$C$13-$C$14))*($C$15/(SUM($C$13:$C$17)-$C$13-$C$14-$C$17))+($C$13/SUM($C$13:$C$17))*($C$16/(SUM($C$13:$C$17)-$C$13))*($C$14/(SUM($C$13:$C$17)-$C$13-$C$16))*($C$15/(SUM($C$13:$C$17)-$C$13-$C$16-$C$14))+($C$13/SUM($C$13:$C$17))*($C$16/(SUM($C$13:$C$17)-$C$13))*($C$17/(SUM($C$13:$C$17)-$C$13-$C$16))*($C$15/(SUM($C$13:$C$17)-$C$13-$C$16-$C$17))+($C$13/SUM($C$13:$C$17))*($C$17/(SUM($C$13:$C$17)-$C$13))*($C$14/(SUM($C$13:$C$17)-$C$13-$C$17))*($C$15/(SUM($C$13:$C$17)-$C$13-$C$17-$C$14))+($C$13/SUM($C$13:$C$17))*($C$17/(SUM($C$13:$C$17)-$C$13))*($C$16/(SUM($C$13:$C$17)-$C$13-$C$17))*($C$15/(SUM($C$13:$C$17)-$C$13-$C$17-$C$16))+($C$14/SUM($C$13:$C$17))*($C$13/(SUM($C$13:$C$17)-$C$14))*($C$16/(SUM($C$13:$C$17)-$C$14-$C$13))*($C$15/(SUM($C$13:$C$17)-$C$14-$C$13-$C$16))+($C$14/SUM($C$13:$C$17))*($C$13/(SUM($C$13:$C$17)-$C$14))*($C$17/(SUM($C$13:$C$17)-$C$14-$C$13))*($C$15/(SUM($C$13:$C$17)-$C$14-$C$13-$C$17))+($C$14/SUM($C$13:$C$17))*($C$16/(SUM($C$13:$C$17)-$C$14))*($C$13/(SUM($C$13:$C$17)-$C$14-$C$16))*($C$15/(SUM($C$13:$C$17)-$C$14-$C$16-$C$13))+($C$14/SUM($C$13:$C$17))*($C$16/(SUM($C$13:$C$17)-$C$14))*($C$17/(SUM($C$13:$C$17)-$C$14-$C$16))*($C$15/(SUM($C$13:$C$17)-$C$14-$C$16-$C$17))+($C$14/SUM($C$13:$C$17))*($C$17/(SUM($C$13:$C$17)-$C$14))*($C$13/(SUM($C$13:$C$17)-$C$14-$C$17))*($C$15/(SUM($C$13:$C$17)-$C$14-$C$17-$C$13))+($C$14/SUM($C$13:$C$17))*($C$17/(SUM($C$13:$C$17)-$C$14))*($C$16/(SUM($C$13:$C$17)-$C$14-$C$17))*($C$15/(SUM($C$13:$C$17)-$C$14-$C$17-$C$16))+($C$16/SUM($C$13:$C$17))*($C$13/(SUM($C$13:$C$17)-$C$16))*($C$14/(SUM($C$13:$C$17)-$C$16-$C$13))*($C$15/(SUM($C$13:$C$17)-$C$16-$C$13-$C$14))+($C$16/SUM($C$13:$C$17))*($C$13/(SUM($C$13:$C$17)-$C$16))*($C$17/(SUM($C$13:$C$17)-$C$16-$C$13))*($C$15/(SUM($C$13:$C$17)-$C$16-$C$13-$C$17))+($C$16/SUM($C$13:$C$17))*($C$14/(SUM($C$13:$C$17)-$C$16))*($C$13/(SUM($C$13:$C$17)-$C$16-$C$14))*($C$15/(SUM($C$13:$C$17)-$C$16-$C$14-$C$13))+($C$16/SUM($C$13:$C$17))*($C$14/(SUM($C$13:$C$17)-$C$16))*($C$17/(SUM($C$13:$C$17)-$C$16-$C$14))*($C$15/(SUM($C$13:$C$17)-$C$16-$C$14-$C$17))+($C$16/SUM($C$13:$C$17))*($C$17/(SUM($C$13:$C$17)-$C$16))*($C$13/(SUM($C$13:$C$17)-$C$16-$C$17))*($C$15/(SUM($C$13:$C$17)-$C$16-$C$17-$C$13))+($C$16/SUM($C$13:$C$17))*($C$17/(SUM($C$13:$C$17)-$C$16))*($C$14/(SUM($C$13:$C$17)-$C$16-$C$17))*($C$15/(SUM($C$13:$C$17)-$C$16-$C$17-$C$14))+($C$17/SUM($C$13:$C$17))*($C$13/(SUM($C$13:$C$17)-$C$17))*($C$14/(SUM($C$13:$C$17)-$C$17-$C$13))*($C$15/(SUM($C$13:$C$17)-$C$17-$C$13-$C$14))+($C$17/SUM($C$13:$C$17))*($C$13/(SUM($C$13:$C$17)-$C$17))*($C$16/(SUM($C$13:$C$17)-$C$17-$C$13))*($C$15/(SUM($C$13:$C$17)-$C$17-$C$13-$C$16))+($C$17/SUM($C$13:$C$17))*($C$14/(SUM($C$13:$C$17)-$C$17))*($C$13/(SUM($C$13:$C$17)-$C$17-$C$14))*($C$15/(SUM($C$13:$C$17)-$C$17-$C$14-$C$13))+($C$17/SUM($C$13:$C$17))*($C$14/(SUM($C$13:$C$17)-$C$17))*($C$16/(SUM($C$13:$C$17)-$C$17-$C$14))*($C$15/(SUM($C$13:$C$17)-$C$17-$C$14-$C$16))+($C$17/SUM($C$13:$C$17))*($C$16/(SUM($C$13:$C$17)-$C$17))*($C$13/(SUM($C$13:$C$17)-$C$17-$C$16))*($C$15/(SUM($C$13:$C$17)-$C$17-$C$16-$C$13))+($C$17/SUM($C$13:$C$17))*($C$16/(SUM($C$13:$C$17)-$C$17))*($C$14/(SUM($C$13:$C$17)-$C$17-$C$16))*($C$15/(SUM($C$13:$C$17)-$C$17-$C$16-$C$14)) -> 0.21802789 | H15: =MIN(1,(IF(AND(0>=$D$11,0<=$F$11),0,0)+IF(AND(1>=$D$11,1<=$F$11),D15,0)+IF(AND(2>=$D$11,2<=$F$11),D15+E15,0)+IF(AND(3>=$D$11,3<=$F$11),D15+E15+F15,0)+IF(AND(4>=$D$11,4<=$F$11),D15+E15+F15+G15,0)+IF(AND(5>=$D$11,5<=$F$11),D15+E15+F15+G15,0)+IF(AND(6>=$D$11,6<=$F$11),D15+E15+F15+G15,0)+IF(AND(7>=$D$11,7<=$F$11),D15+E15+F15+G15,0)+IF(AND(8>=$D$11,8<=$F$11),D15+E15+F15+G15,0))/($F$11-$D$11+1)) -> 0.52872475 | I15: Road lore (70 ash) | J15: Iron nails 2-3 | L15: teaches studded_wrap · scavenge · strength 55 XP · 4s
A16: tower_marks | B16: Scratched warnings | C16: =Encounters!F55 -> 6 | D16: =$C$16/SUM($C$13:$C$17) -> 0.1875 | E16: =($C$13/SUM($C$13:$C$17))*($C$16/(SUM($C$13:$C$17)-$C$13))+($C$14/SUM($C$13:$C$17))*($C$16/(SUM($C$13:$C$17)-$C$14))+($C$15/SUM($C$13:$C$17))*($C$16/(SUM($C$13:$C$17)-$C$15))+($C$17/SUM($C$13:$C$17))*($C$16/(SUM($C$13:$C$17)-$C$17)) -> 0.19794095 | F16: =($C$13/SUM($C$13:$C$17))*($C$14/(SUM($C$13:$C$17)-$C$13))*($C$16/(SUM($C$13:$C$17)-$C$13-$C$14))+($C$13/SUM($C$13:$C$17))*($C$15/(SUM($C$13:$C$17)-$C$13))*($C$16/(SUM($C$13:$C$17)-$C$13-$C$15))+($C$13/SUM($C$13:$C$17))*($C$17/(SUM($C$13:$C$17)-$C$13))*($C$16/(SUM($C$13:$C$17)-$C$13-$C$17))+($C$14/SUM($C$13:$C$17))*($C$13/(SUM($C$13:$C$17)-$C$14))*($C$16/(SUM($C$13:$C$17)-$C$14-$C$13))+($C$14/SUM($C$13:$C$17))*($C$15/(SUM($C$13:$C$17)-$C$14))*($C$16/(SUM($C$13:$C$17)-$C$14-$C$15))+($C$14/SUM($C$13:$C$17))*($C$17/(SUM($C$13:$C$17)-$C$14))*($C$16/(SUM($C$13:$C$17)-$C$14-$C$17))+($C$15/SUM($C$13:$C$17))*($C$13/(SUM($C$13:$C$17)-$C$15))*($C$16/(SUM($C$13:$C$17)-$C$15-$C$13))+($C$15/SUM($C$13:$C$17))*($C$14/(SUM($C$13:$C$17)-$C$15))*($C$16/(SUM($C$13:$C$17)-$C$15-$C$14))+($C$15/SUM($C$13:$C$17))*($C$17/(SUM($C$13:$C$17)-$C$15))*($C$16/(SUM($C$13:$C$17)-$C$15-$C$17))+($C$17/SUM($C$13:$C$17))*($C$13/(SUM($C$13:$C$17)-$C$17))*($C$16/(SUM($C$13:$C$17)-$C$17-$C$13))+($C$17/SUM($C$13:$C$17))*($C$14/(SUM($C$13:$C$17)-$C$17))*($C$16/(SUM($C$13:$C$17)-$C$17-$C$14))+($C$17/SUM($C$13:$C$17))*($C$15/(SUM($C$13:$C$17)-$C$17))*($C$16/(SUM($C$13:$C$17)-$C$17-$C$15)) -> 0.20621535 | G16: =($C$13/SUM($C$13:$C$17))*($C$14/(SUM($C$13:$C$17)-$C$13))*($C$15/(SUM($C$13:$C$17)-$C$13-$C$14))*($C$16/(SUM($C$13:$C$17)-$C$13-$C$14-$C$15))+($C$13/SUM($C$13:$C$17))*($C$14/(SUM($C$13:$C$17)-$C$13))*($C$17/(SUM($C$13:$C$17)-$C$13-$C$14))*($C$16/(SUM($C$13:$C$17)-$C$13-$C$14-$C$17))+($C$13/SUM($C$13:$C$17))*($C$15/(SUM($C$13:$C$17)-$C$13))*($C$14/(SUM($C$13:$C$17)-$C$13-$C$15))*($C$16/(SUM($C$13:$C$17)-$C$13-$C$15-$C$14))+($C$13/SUM($C$13:$C$17))*($C$15/(SUM($C$13:$C$17)-$C$13))*($C$17/(SUM($C$13:$C$17)-$C$13-$C$15))*($C$16/(SUM($C$13:$C$17)-$C$13-$C$15-$C$17))+($C$13/SUM($C$13:$C$17))*($C$17/(SUM($C$13:$C$17)-$C$13))*($C$14/(SUM($C$13:$C$17)-$C$13-$C$17))*($C$16/(SUM($C$13:$C$17)-$C$13-$C$17-$C$14))+($C$13/SUM($C$13:$C$17))*($C$17/(SUM($C$13:$C$17)-$C$13))*($C$15/(SUM($C$13:$C$17)-$C$13-$C$17))*($C$16/(SUM($C$13:$C$17)-$C$13-$C$17-$C$15))+($C$14/SUM($C$13:$C$17))*($C$13/(SUM($C$13:$C$17)-$C$14))*($C$15/(SUM($C$13:$C$17)-$C$14-$C$13))*($C$16/(SUM($C$13:$C$17)-$C$14-$C$13-$C$15))+($C$14/SUM($C$13:$C$17))*($C$13/(SUM($C$13:$C$17)-$C$14))*($C$17/(SUM($C$13:$C$17)-$C$14-$C$13))*($C$16/(SUM($C$13:$C$17)-$C$14-$C$13-$C$17))+($C$14/SUM($C$13:$C$17))*($C$15/(SUM($C$13:$C$17)-$C$14))*($C$13/(SUM($C$13:$C$17)-$C$14-$C$15))*($C$16/(SUM($C$13:$C$17)-$C$14-$C$15-$C$13))+($C$14/SUM($C$13:$C$17))*($C$15/(SUM($C$13:$C$17)-$C$14))*($C$17/(SUM($C$13:$C$17)-$C$14-$C$15))*($C$16/(SUM($C$13:$C$17)-$C$14-$C$15-$C$17))+($C$14/SUM($C$13:$C$17))*($C$17/(SUM($C$13:$C$17)-$C$14))*($C$13/(SUM($C$13:$C$17)-$C$14-$C$17))*($C$16/(SUM($C$13:$C$17)-$C$14-$C$17-$C$13))+($C$14/SUM($C$13:$C$17))*($C$17/(SUM($C$13:$C$17)-$C$14))*($C$15/(SUM($C$13:$C$17)-$C$14-$C$17))*($C$16/(SUM($C$13:$C$17)-$C$14-$C$17-$C$15))+($C$15/SUM($C$13:$C$17))*($C$13/(SUM($C$13:$C$17)-$C$15))*($C$14/(SUM($C$13:$C$17)-$C$15-$C$13))*($C$16/(SUM($C$13:$C$17)-$C$15-$C$13-$C$14))+($C$15/SUM($C$13:$C$17))*($C$13/(SUM($C$13:$C$17)-$C$15))*($C$17/(SUM($C$13:$C$17)-$C$15-$C$13))*($C$16/(SUM($C$13:$C$17)-$C$15-$C$13-$C$17))+($C$15/SUM($C$13:$C$17))*($C$14/(SUM($C$13:$C$17)-$C$15))*($C$13/(SUM($C$13:$C$17)-$C$15-$C$14))*($C$16/(SUM($C$13:$C$17)-$C$15-$C$14-$C$13))+($C$15/SUM($C$13:$C$17))*($C$14/(SUM($C$13:$C$17)-$C$15))*($C$17/(SUM($C$13:$C$17)-$C$15-$C$14))*($C$16/(SUM($C$13:$C$17)-$C$15-$C$14-$C$17))+($C$15/SUM($C$13:$C$17))*($C$17/(SUM($C$13:$C$17)-$C$15))*($C$13/(SUM($C$13:$C$17)-$C$15-$C$17))*($C$16/(SUM($C$13:$C$17)-$C$15-$C$17-$C$13))+($C$15/SUM($C$13:$C$17))*($C$17/(SUM($C$13:$C$17)-$C$15))*($C$14/(SUM($C$13:$C$17)-$C$15-$C$17))*($C$16/(SUM($C$13:$C$17)-$C$15-$C$17-$C$14))+($C$17/SUM($C$13:$C$17))*($C$13/(SUM($C$13:$C$17)-$C$17))*($C$14/(SUM($C$13:$C$17)-$C$17-$C$13))*($C$16/(SUM($C$13:$C$17)-$C$17-$C$13-$C$14))+($C$17/SUM($C$13:$C$17))*($C$13/(SUM($C$13:$C$17)-$C$17))*($C$15/(SUM($C$13:$C$17)-$C$17-$C$13))*($C$16/(SUM($C$13:$C$17)-$C$17-$C$13-$C$15))+($C$17/SUM($C$13:$C$17))*($C$14/(SUM($C$13:$C$17)-$C$17))*($C$13/(SUM($C$13:$C$17)-$C$17-$C$14))*($C$16/(SUM($C$13:$C$17)-$C$17-$C$14-$C$13))+($C$17/SUM($C$13:$C$17))*($C$14/(SUM($C$13:$C$17)-$C$17))*($C$15/(SUM($C$13:$C$17)-$C$17-$C$14))*($C$16/(SUM($C$13:$C$17)-$C$17-$C$14-$C$15))+($C$17/SUM($C$13:$C$17))*($C$15/(SUM($C$13:$C$17)-$C$17))*($C$13/(SUM($C$13:$C$17)-$C$17-$C$15))*($C$16/(SUM($C$13:$C$17)-$C$17-$C$15-$C$13))+($C$17/SUM($C$13:$C$17))*($C$15/(SUM($C$13:$C$17)-$C$17))*($C$14/(SUM($C$13:$C$17)-$C$17-$C$15))*($C$16/(SUM($C$13:$C$17)-$C$17-$C$15-$C$14)) -> 0.20965554 | H16: =MIN(1,(IF(AND(0>=$D$11,0<=$F$11),0,0)+IF(AND(1>=$D$11,1<=$F$11),D16,0)+IF(AND(2>=$D$11,2<=$F$11),D16+E16,0)+IF(AND(3>=$D$11,3<=$F$11),D16+E16+F16,0)+IF(AND(4>=$D$11,4<=$F$11),D16+E16+F16+G16,0)+IF(AND(5>=$D$11,5<=$F$11),D16+E16+F16+G16,0)+IF(AND(6>=$D$11,6<=$F$11),D16+E16+F16+G16,0)+IF(AND(7>=$D$11,7<=$F$11),D16+E16+F16+G16,0)+IF(AND(8>=$D$11,8<=$F$11),D16+E16+F16+G16,0))/($F$11-$D$11+1)) -> 0.59280303 | I16: Road lore (70 ash) | L16: study · intelligence 75 XP · 4.2s
A17: tower_guard | B17: Fallen guard | C17: =Encounters!F69 -> 5 | D17: =$C$17/SUM($C$13:$C$17) -> 0.15625 | E17: =($C$13/SUM($C$13:$C$17))*($C$17/(SUM($C$13:$C$17)-$C$13))+($C$14/SUM($C$13:$C$17))*($C$17/(SUM($C$13:$C$17)-$C$14))+($C$15/SUM($C$13:$C$17))*($C$17/(SUM($C$13:$C$17)-$C$15))+($C$16/SUM($C$13:$C$17))*($C$17/(SUM($C$13:$C$17)-$C$16)) -> 0.1720733 | F17: =($C$13/SUM($C$13:$C$17))*($C$14/(SUM($C$13:$C$17)-$C$13))*($C$17/(SUM($C$13:$C$17)-$C$13-$C$14))+($C$13/SUM($C$13:$C$17))*($C$15/(SUM($C$13:$C$17)-$C$13))*($C$17/(SUM($C$13:$C$17)-$C$13-$C$15))+($C$13/SUM($C$13:$C$17))*($C$16/(SUM($C$13:$C$17)-$C$13))*($C$17/(SUM($C$13:$C$17)-$C$13-$C$16))+($C$14/SUM($C$13:$C$17))*($C$13/(SUM($C$13:$C$17)-$C$14))*($C$17/(SUM($C$13:$C$17)-$C$14-$C$13))+($C$14/SUM($C$13:$C$17))*($C$15/(SUM($C$13:$C$17)-$C$14))*($C$17/(SUM($C$13:$C$17)-$C$14-$C$15))+($C$14/SUM($C$13:$C$17))*($C$16/(SUM($C$13:$C$17)-$C$14))*($C$17/(SUM($C$13:$C$17)-$C$14-$C$16))+($C$15/SUM($C$13:$C$17))*($C$13/(SUM($C$13:$C$17)-$C$15))*($C$17/(SUM($C$13:$C$17)-$C$15-$C$13))+($C$15/SUM($C$13:$C$17))*($C$14/(SUM($C$13:$C$17)-$C$15))*($C$17/(SUM($C$13:$C$17)-$C$15-$C$14))+($C$15/SUM($C$13:$C$17))*($C$16/(SUM($C$13:$C$17)-$C$15))*($C$17/(SUM($C$13:$C$17)-$C$15-$C$16))+($C$16/SUM($C$13:$C$17))*($C$13/(SUM($C$13:$C$17)-$C$16))*($C$17/(SUM($C$13:$C$17)-$C$16-$C$13))+($C$16/SUM($C$13:$C$17))*($C$14/(SUM($C$13:$C$17)-$C$16))*($C$17/(SUM($C$13:$C$17)-$C$16-$C$14))+($C$16/SUM($C$13:$C$17))*($C$15/(SUM($C$13:$C$17)-$C$16))*($C$17/(SUM($C$13:$C$17)-$C$16-$C$15)) -> 0.19158823 | G17: =($C$13/SUM($C$13:$C$17))*($C$14/(SUM($C$13:$C$17)-$C$13))*($C$15/(SUM($C$13:$C$17)-$C$13-$C$14))*($C$17/(SUM($C$13:$C$17)-$C$13-$C$14-$C$15))+($C$13/SUM($C$13:$C$17))*($C$14/(SUM($C$13:$C$17)-$C$13))*($C$16/(SUM($C$13:$C$17)-$C$13-$C$14))*($C$17/(SUM($C$13:$C$17)-$C$13-$C$14-$C$16))+($C$13/SUM($C$13:$C$17))*($C$15/(SUM($C$13:$C$17)-$C$13))*($C$14/(SUM($C$13:$C$17)-$C$13-$C$15))*($C$17/(SUM($C$13:$C$17)-$C$13-$C$15-$C$14))+($C$13/SUM($C$13:$C$17))*($C$15/(SUM($C$13:$C$17)-$C$13))*($C$16/(SUM($C$13:$C$17)-$C$13-$C$15))*($C$17/(SUM($C$13:$C$17)-$C$13-$C$15-$C$16))+($C$13/SUM($C$13:$C$17))*($C$16/(SUM($C$13:$C$17)-$C$13))*($C$14/(SUM($C$13:$C$17)-$C$13-$C$16))*($C$17/(SUM($C$13:$C$17)-$C$13-$C$16-$C$14))+($C$13/SUM($C$13:$C$17))*($C$16/(SUM($C$13:$C$17)-$C$13))*($C$15/(SUM($C$13:$C$17)-$C$13-$C$16))*($C$17/(SUM($C$13:$C$17)-$C$13-$C$16-$C$15))+($C$14/SUM($C$13:$C$17))*($C$13/(SUM($C$13:$C$17)-$C$14))*($C$15/(SUM($C$13:$C$17)-$C$14-$C$13))*($C$17/(SUM($C$13:$C$17)-$C$14-$C$13-$C$15))+($C$14/SUM($C$13:$C$17))*($C$13/(SUM($C$13:$C$17)-$C$14))*($C$16/(SUM($C$13:$C$17)-$C$14-$C$13))*($C$17/(SUM($C$13:$C$17)-$C$14-$C$13-$C$16))+($C$14/SUM($C$13:$C$17))*($C$15/(SUM($C$13:$C$17)-$C$14))*($C$13/(SUM($C$13:$C$17)-$C$14-$C$15))*($C$17/(SUM($C$13:$C$17)-$C$14-$C$15-$C$13))+($C$14/SUM($C$13:$C$17))*($C$15/(SUM($C$13:$C$17)-$C$14))*($C$16/(SUM($C$13:$C$17)-$C$14-$C$15))*($C$17/(SUM($C$13:$C$17)-$C$14-$C$15-$C$16))+($C$14/SUM($C$13:$C$17))*($C$16/(SUM($C$13:$C$17)-$C$14))*($C$13/(SUM($C$13:$C$17)-$C$14-$C$16))*($C$17/(SUM($C$13:$C$17)-$C$14-$C$16-$C$13))+($C$14/SUM($C$13:$C$17))*($C$16/(SUM($C$13:$C$17)-$C$14))*($C$15/(SUM($C$13:$C$17)-$C$14-$C$16))*($C$17/(SUM($C$13:$C$17)-$C$14-$C$16-$C$15))+($C$15/SUM($C$13:$C$17))*($C$13/(SUM($C$13:$C$17)-$C$15))*($C$14/(SUM($C$13:$C$17)-$C$15-$C$13))*($C$17/(SUM($C$13:$C$17)-$C$15-$C$13-$C$14))+($C$15/SUM($C$13:$C$17))*($C$13/(SUM($C$13:$C$17)-$C$15))*($C$16/(SUM($C$13:$C$17)-$C$15-$C$13))*($C$17/(SUM($C$13:$C$17)-$C$15-$C$13-$C$16))+($C$15/SUM($C$13:$C$17))*($C$14/(SUM($C$13:$C$17)-$C$15))*($C$13/(SUM($C$13:$C$17)-$C$15-$C$14))*($C$17/(SUM($C$13:$C$17)-$C$15-$C$14-$C$13))+($C$15/SUM($C$13:$C$17))*($C$14/(SUM($C$13:$C$17)-$C$15))*($C$16/(SUM($C$13:$C$17)-$C$15-$C$14))*($C$17/(SUM($C$13:$C$17)-$C$15-$C$14-$C$16))+($C$15/SUM($C$13:$C$17))*($C$16/(SUM($C$13:$C$17)-$C$15))*($C$13/(SUM($C$13:$C$17)-$C$15-$C$16))*($C$17/(SUM($C$13:$C$17)-$C$15-$C$16-$C$13))+($C$15/SUM($C$13:$C$17))*($C$16/(SUM($C$13:$C$17)-$C$15))*($C$14/(SUM($C$13:$C$17)-$C$15-$C$16))*($C$17/(SUM($C$13:$C$17)-$C$15-$C$16-$C$14))+($C$16/SUM($C$13:$C$17))*($C$13/(SUM($C$13:$C$17)-$C$16))*($C$14/(SUM($C$13:$C$17)-$C$16-$C$13))*($C$17/(SUM($C$13:$C$17)-$C$16-$C$13-$C$14))+($C$16/SUM($C$13:$C$17))*($C$13/(SUM($C$13:$C$17)-$C$16))*($C$15/(SUM($C$13:$C$17)-$C$16-$C$13))*($C$17/(SUM($C$13:$C$17)-$C$16-$C$13-$C$15))+($C$16/SUM($C$13:$C$17))*($C$14/(SUM($C$13:$C$17)-$C$16))*($C$13/(SUM($C$13:$C$17)-$C$16-$C$14))*($C$17/(SUM($C$13:$C$17)-$C$16-$C$14-$C$13))+($C$16/SUM($C$13:$C$17))*($C$14/(SUM($C$13:$C$17)-$C$16))*($C$15/(SUM($C$13:$C$17)-$C$16-$C$14))*($C$17/(SUM($C$13:$C$17)-$C$16-$C$14-$C$15))+($C$16/SUM($C$13:$C$17))*($C$15/(SUM($C$13:$C$17)-$C$16))*($C$13/(SUM($C$13:$C$17)-$C$16-$C$15))*($C$17/(SUM($C$13:$C$17)-$C$16-$C$15-$C$13))+($C$16/SUM($C$13:$C$17))*($C$15/(SUM($C$13:$C$17)-$C$16))*($C$14/(SUM($C$13:$C$17)-$C$16-$C$15))*($C$17/(SUM($C$13:$C$17)-$C$16-$C$15-$C$14)) -> 0.21802789 | H17: =MIN(1,(IF(AND(0>=$D$11,0<=$F$11),0,0)+IF(AND(1>=$D$11,1<=$F$11),D17,0)+IF(AND(2>=$D$11,2<=$F$11),D17+E17,0)+IF(AND(3>=$D$11,3<=$F$11),D17+E17+F17,0)+IF(AND(4>=$D$11,4<=$F$11),D17+E17+F17+G17,0)+IF(AND(5>=$D$11,5<=$F$11),D17+E17+F17+G17,0)+IF(AND(6>=$D$11,6<=$F$11),D17+E17+F17+G17,0)+IF(AND(7>=$D$11,7<=$F$11),D17+E17+F17+G17,0)+IF(AND(8>=$D$11,8<=$F$11),D17+E17+F17+G17,0))/($F$11-$D$11+1)) -> 0.52872475 | I17: start | J17: Carved bone 1-1, Iron nails 1-1 (50%) | K17: bones_spoils | L17: fight · strength 90 XP · 0.001s
B18: Check: picks per life | H18: =SUM(H13:H17) -> 3
A20: Logging camp | C20: Min | D20: 2 | E20: Max | F20: 3 | G20: structure: lumber · min ring 2 · uncommon
A21: ID | B21: Name | C21: Weight (Encounters sheet) | D21: P(1st pick) | E21: P(2nd pick) | F21: P(3rd pick) | G21: P(4th pick) | H21: P(shows up in a life) | I21: Unlock | J21: Fixed loot | K21: Bonus table | L21: Other
A22: lumber_logs | B22: Log pile | C22: =Encounters!F56 -> 10 | D22: =$C$22/SUM($C$22:$C$24) -> 0.41666667 | E22: =($C$23/SUM($C$22:$C$24))*($C$22/(SUM($C$22:$C$24)-$C$23))+($C$24/SUM($C$22:$C$24))*($C$22/(SUM($C$22:$C$24)-$C$24)) -> 0.34722222 | F22: =($C$23/SUM($C$22:$C$24))*($C$24/(SUM($C$22:$C$24)-$C$23))*($C$22/(SUM($C$22:$C$24)-$C$23-$C$24))+($C$24/SUM($C$22:$C$24))*($C$23/(SUM($C$22:$C$24)-$C$24))*($C$22/(SUM($C$22:$C$24)-$C$24-$C$23)) -> 0.23611111 | G22: =0 -> 0 | H22: =MIN(1,(IF(AND(0>=$D$20,0<=$F$20),0,0)+IF(AND(1>=$D$20,1<=$F$20),D22,0)+IF(AND(2>=$D$20,2<=$F$20),D22+E22,0)+IF(AND(3>=$D$20,3<=$F$20),D22+E22+F22,0)+IF(AND(4>=$D$20,4<=$F$20),D22+E22+F22+G22,0)+IF(AND(5>=$D$20,5<=$F$20),D22+E22+F22+G22,0)+IF(AND(6>=$D$20,6<=$F$20),D22+E22+F22+G22,0)+IF(AND(7>=$D$20,7<=$F$20),D22+E22+F22+G22,0)+IF(AND(8>=$D$20,8<=$F$20),D22+E22+F22+G22,0))/($F$20-$D$20+1)) -> 0.88194444 | I22: Scavenging (20 ash) | J22: Stick 2-3 | L22: gather · strength 40 XP · 3s
A23: lumber_shed | B23: Tool shed | C23: =Encounters!F57 -> 8 | D23: =$C$23/SUM($C$22:$C$24) -> 0.33333333 | E23: =($C$22/SUM($C$22:$C$24))*($C$23/(SUM($C$22:$C$24)-$C$22))+($C$24/SUM($C$22:$C$24))*($C$23/(SUM($C$22:$C$24)-$C$24)) -> 0.34920635 | F23: =($C$22/SUM($C$22:$C$24))*($C$24/(SUM($C$22:$C$24)-$C$22))*($C$23/(SUM($C$22:$C$24)-$C$22-$C$24))+($C$24/SUM($C$22:$C$24))*($C$22/(SUM($C$22:$C$24)-$C$24))*($C$23/(SUM($C$22:$C$24)-$C$24-$C$22)) -> 0.31746032 | G23: =0 -> 0 | H23: =MIN(1,(IF(AND(0>=$D$20,0<=$F$20),0,0)+IF(AND(1>=$D$20,1<=$F$20),D23,0)+IF(AND(2>=$D$20,2<=$F$20),D23+E23,0)+IF(AND(3>=$D$20,3<=$F$20),D23+E23+F23,0)+IF(AND(4>=$D$20,4<=$F$20),D23+E23+F23+G23,0)+IF(AND(5>=$D$20,5<=$F$20),D23+E23+F23+G23,0)+IF(AND(6>=$D$20,6<=$F$20),D23+E23+F23+G23,0)+IF(AND(7>=$D$20,7<=$F$20),D23+E23+F23+G23,0)+IF(AND(8>=$D$20,8<=$F$20),D23+E23+F23+G23,0))/($F$20-$D$20+1)) -> 0.84126984 | I23: Scavenging (20 ash) | J23: Coil of rope 1-1 (70%), Iron nails 1-2 (60%) | K23: traveller_cache | L23: teaches axe · scavenge · perception 45 XP · 3.2s
A24: lumber_oak | B24: Fallen tree | C24: =Encounters!F58 -> 6 | D24: =$C$24/SUM($C$22:$C$24) -> 0.25 | E24: =($C$22/SUM($C$22:$C$24))*($C$24/(SUM($C$22:$C$24)-$C$22))+($C$23/SUM($C$22:$C$24))*($C$24/(SUM($C$22:$C$24)-$C$23)) -> 0.30357143 | F24: =($C$22/SUM($C$22:$C$24))*($C$23/(SUM($C$22:$C$24)-$C$22))*($C$24/(SUM($C$22:$C$24)-$C$22-$C$23))+($C$23/SUM($C$22:$C$24))*($C$22/(SUM($C$22:$C$24)-$C$23))*($C$24/(SUM($C$22:$C$24)-$C$23-$C$22)) -> 0.44642857 | G24: =0 -> 0 | H24: =MIN(1,(IF(AND(0>=$D$20,0<=$F$20),0,0)+IF(AND(1>=$D$20,1<=$F$20),D24,0)+IF(AND(2>=$D$20,2<=$F$20),D24+E24,0)+IF(AND(3>=$D$20,3<=$F$20),D24+E24+F24,0)+IF(AND(4>=$D$20,4<=$F$20),D24+E24+F24+G24,0)+IF(AND(5>=$D$20,5<=$F$20),D24+E24+F24+G24,0)+IF(AND(6>=$D$20,6<=$F$20),D24+E24+F24+G24,0)+IF(AND(7>=$D$20,7<=$F$20),D24+E24+F24+G24,0)+IF(AND(8>=$D$20,8<=$F$20),D24+E24+F24+G24,0))/($F$20-$D$20+1)) -> 0.77678571 | I24: Scavenging (20 ash) | J24: Bird egg 1-2 (70%), Stick 1-2 | L24: climb · agility 50 XP · 3s
B25: Check: picks per life | H25: =SUM(H22:H24) -> 2.5
A27: Hunter's cabin | C27: Min | D27: 2 | E27: Max | F27: 3 | G27: structure: lodge · min ring 3 · uncommon
A28: ID | B28: Name | C28: Weight (Encounters sheet) | D28: P(1st pick) | E28: P(2nd pick) | F28: P(3rd pick) | G28: P(4th pick) | H28: P(shows up in a life) | I28: Unlock | J28: Fixed loot | K28: Bonus table | L28: Other
A29: lodge_racks | B29: Hide racks | C29: =Encounters!F59 -> 9 | D29: =$C$29/SUM($C$29:$C$31) -> 0.40909091 | E29: =($C$30/SUM($C$29:$C$31))*($C$29/(SUM($C$29:$C$31)-$C$30))+($C$31/SUM($C$29:$C$31))*($C$29/(SUM($C$29:$C$31)-$C$31)) -> 0.35408709 | F29: =($C$30/SUM($C$29:$C$31))*($C$31/(SUM($C$29:$C$31)-$C$30))*($C$29/(SUM($C$29:$C$31)-$C$30-$C$31))+($C$31/SUM($C$29:$C$31))*($C$30/(SUM($C$29:$C$31)-$C$31))*($C$29/(SUM($C$29:$C$31)-$C$31-$C$30)) -> 0.236822 | G29: =0 -> 0 | H29: =MIN(1,(IF(AND(0>=$D$27,0<=$F$27),0,0)+IF(AND(1>=$D$27,1<=$F$27),D29,0)+IF(AND(2>=$D$27,2<=$F$27),D29+E29,0)+IF(AND(3>=$D$27,3<=$F$27),D29+E29+F29,0)+IF(AND(4>=$D$27,4<=$F$27),D29+E29+F29+G29,0)+IF(AND(5>=$D$27,5<=$F$27),D29+E29+F29+G29,0)+IF(AND(6>=$D$27,6<=$F$27),D29+E29+F29+G29,0)+IF(AND(7>=$D$27,7<=$F$27),D29+E29+F29+G29,0)+IF(AND(8>=$D$27,8<=$F$27),D29+E29+F29+G29,0))/($F$27-$D$27+1)) -> 0.881589 | I29: Snares (25 ash) | J29: Boar hide 1-2, Coil of rope 1-1 (40%) | L29: scavenge · strength 45 XP · 3.4s
A30: lodge_snares | B30: Old traps | C30: =Encounters!F60 -> 8 | D30: =$C$30/SUM($C$29:$C$31) -> 0.36363636 | E30: =($C$29/SUM($C$29:$C$31))*($C$30/(SUM($C$29:$C$31)-$C$29))+($C$31/SUM($C$29:$C$31))*($C$30/(SUM($C$29:$C$31)-$C$31)) -> 0.35870012 | F30: =($C$29/SUM($C$29:$C$31))*($C$31/(SUM($C$29:$C$31)-$C$29))*($C$30/(SUM($C$29:$C$31)-$C$29-$C$31))+($C$31/SUM($C$29:$C$31))*($C$29/(SUM($C$29:$C$31)-$C$31))*($C$30/(SUM($C$29:$C$31)-$C$31-$C$29)) -> 0.27766351 | G30: =0 -> 0 | H30: =MIN(1,(IF(AND(0>=$D$27,0<=$F$27),0,0)+IF(AND(1>=$D$27,1<=$F$27),D30,0)+IF(AND(2>=$D$27,2<=$F$27),D30+E30,0)+IF(AND(3>=$D$27,3<=$F$27),D30+E30+F30,0)+IF(AND(4>=$D$27,4<=$F$27),D30+E30+F30+G30,0)+IF(AND(5>=$D$27,5<=$F$27),D30+E30+F30+G30,0)+IF(AND(6>=$D$27,6<=$F$27),D30+E30+F30+G30,0)+IF(AND(7>=$D$27,7<=$F$27),D30+E30+F30+G30,0)+IF(AND(8>=$D$27,8<=$F$27),D30+E30+F30+G30,0))/($F$27-$D$27+1)) -> 0.86116824 | I30: Snares (25 ash) | J30: Snared hare 1-1 (70%), Bramble thorn 1-2 | L30: hunt · perception 45 XP · 3s
A31: lodge_trophies | B31: Antler wall | C31: =Encounters!F61 -> 5 | D31: =$C$31/SUM($C$29:$C$31) -> 0.22727273 | E31: =($C$29/SUM($C$29:$C$31))*($C$31/(SUM($C$29:$C$31)-$C$29))+($C$30/SUM($C$29:$C$31))*($C$31/(SUM($C$29:$C$31)-$C$30)) -> 0.28721279 | F31: =($C$29/SUM($C$29:$C$31))*($C$30/(SUM($C$29:$C$31)-$C$29))*($C$31/(SUM($C$29:$C$31)-$C$29-$C$30))+($C$30/SUM($C$29:$C$31))*($C$29/(SUM($C$29:$C$31)-$C$30))*($C$31/(SUM($C$29:$C$31)-$C$30-$C$29)) -> 0.48551449 | G31: =0 -> 0 | H31: =MIN(1,(IF(AND(0>=$D$27,0<=$F$27),0,0)+IF(AND(1>=$D$27,1<=$F$27),D31,0)+IF(AND(2>=$D$27,2<=$F$27),D31+E31,0)+IF(AND(3>=$D$27,3<=$F$27),D31+E31+F31,0)+IF(AND(4>=$D$27,4<=$F$27),D31+E31+F31+G31,0)+IF(AND(5>=$D$27,5<=$F$27),D31+E31+F31+G31,0)+IF(AND(6>=$D$27,6<=$F$27),D31+E31+F31+G31,0)+IF(AND(7>=$D$27,7<=$F$27),D31+E31+F31+G31,0)+IF(AND(8>=$D$27,8<=$F$27),D31+E31+F31+G31,0))/($F$27-$D$27+1)) -> 0.75724276 | I31: Snares (25 ash) | K31: hunter_trophies | L31: teaches spear · scavenge · intelligence 55 XP · 3.6s
B32: Check: picks per life | H32: =SUM(H29:H31) -> 2.5
A34: Ruined shrine | C34: Min | D34: 2 | E34: Max | F34: 3 | G34: structure: shrine · min ring 4 · rare
A35: ID | B35: Name | C35: Weight (Encounters sheet) | D35: P(1st pick) | E35: P(2nd pick) | F35: P(3rd pick) | G35: P(4th pick) | H35: P(shows up in a life) | I35: Unlock | J35: Fixed loot | K35: Bonus table | L35: Other
A36: shrine_altar | B36: Broken altar | C36: =Encounters!F62 -> 8 | D36: =$C$36/SUM($C$36:$C$39) -> 0.2962963 | E36: =($C$37/SUM($C$36:$C$39))*($C$36/(SUM($C$36:$C$39)-$C$37))+($C$38/SUM($C$36:$C$39))*($C$36/(SUM($C$36:$C$39)-$C$38))+($C$39/SUM($C$36:$C$39))*($C$36/(SUM($C$36:$C$39)-$C$39)) -> 0.27301587 | F36: =($C$37/SUM($C$36:$C$39))*($C$38/(SUM($C$36:$C$39)-$C$37))*($C$36/(SUM($C$36:$C$39)-$C$37-$C$38))+($C$37/SUM($C$36:$C$39))*($C$39/(SUM($C$36:$C$39)-$C$37))*($C$36/(SUM($C$36:$C$39)-$C$37-$C$39))+($C$38/SUM($C$36:$C$39))*($C$37/(SUM($C$36:$C$39)-$C$38))*($C$36/(SUM($C$36:$C$39)-$C$38-$C$37))+($C$38/SUM($C$36:$C$39))*($C$39/(SUM($C$36:$C$39)-$C$38))*($C$36/(SUM($C$36:$C$39)-$C$38-$C$39))+($C$39/SUM($C$36:$C$39))*($C$37/(SUM($C$36:$C$39)-$C$39))*($C$36/(SUM($C$36:$C$39)-$C$39-$C$37))+($C$39/SUM($C$36:$C$39))*($C$38/(SUM($C$36:$C$39)-$C$39))*($C$36/(SUM($C$36:$C$39)-$C$39-$C$38)) -> 0.24126984 | G36: =($C$37/SUM($C$36:$C$39))*($C$38/(SUM($C$36:$C$39)-$C$37))*($C$39/(SUM($C$36:$C$39)-$C$37-$C$38))*($C$36/(SUM($C$36:$C$39)-$C$37-$C$38-$C$39))+($C$37/SUM($C$36:$C$39))*($C$39/(SUM($C$36:$C$39)-$C$37))*($C$38/(SUM($C$36:$C$39)-$C$37-$C$39))*($C$36/(SUM($C$36:$C$39)-$C$37-$C$39-$C$38))+($C$38/SUM($C$36:$C$39))*($C$37/(SUM($C$36:$C$39)-$C$38))*($C$39/(SUM($C$36:$C$39)-$C$38-$C$37))*($C$36/(SUM($C$36:$C$39)-$C$38-$C$37-$C$39))+($C$38/SUM($C$36:$C$39))*($C$39/(SUM($C$36:$C$39)-$C$38))*($C$37/(SUM($C$36:$C$39)-$C$38-$C$39))*($C$36/(SUM($C$36:$C$39)-$C$38-$C$39-$C$37))+($C$39/SUM($C$36:$C$39))*($C$37/(SUM($C$36:$C$39)-$C$39))*($C$38/(SUM($C$36:$C$39)-$C$39-$C$37))*($C$36/(SUM($C$36:$C$39)-$C$39-$C$37-$C$38))+($C$39/SUM($C$36:$C$39))*($C$38/(SUM($C$36:$C$39)-$C$39))*($C$37/(SUM($C$36:$C$39)-$C$39-$C$38))*($C$36/(SUM($C$36:$C$39)-$C$39-$C$38-$C$37)) -> 0.18941799 | H36: =MIN(1,(IF(AND(0>=$D$34,0<=$F$34),0,0)+IF(AND(1>=$D$34,1<=$F$34),D36,0)+IF(AND(2>=$D$34,2<=$F$34),D36+E36,0)+IF(AND(3>=$D$34,3<=$F$34),D36+E36+F36,0)+IF(AND(4>=$D$34,4<=$F$34),D36+E36+F36+G36,0)+IF(AND(5>=$D$34,5<=$F$34),D36+E36+F36+G36,0)+IF(AND(6>=$D$34,6<=$F$34),D36+E36+F36+G36,0)+IF(AND(7>=$D$34,7<=$F$34),D36+E36+F36+G36,0)+IF(AND(8>=$D$34,8<=$F$34),D36+E36+F36+G36,0))/($F$34-$D$34+1)) -> 0.68994709 | I36: Shrine path (3 blessing) | L36: +1 blessing · pray · willpower 60 XP · 4.2s
A37: shrine_offerings | B37: Coin bowls | C37: =Encounters!F63 -> 7 | D37: =$C$37/SUM($C$36:$C$39) -> 0.25925926 | E37: =($C$36/SUM($C$36:$C$39))*($C$37/(SUM($C$36:$C$39)-$C$36))+($C$38/SUM($C$36:$C$39))*($C$37/(SUM($C$36:$C$39)-$C$38))+($C$39/SUM($C$36:$C$39))*($C$37/(SUM($C$36:$C$39)-$C$39)) -> 0.25730994 | F37: =($C$36/SUM($C$36:$C$39))*($C$38/(SUM($C$36:$C$39)-$C$36))*($C$37/(SUM($C$36:$C$39)-$C$36-$C$38))+($C$36/SUM($C$36:$C$39))*($C$39/(SUM($C$36:$C$39)-$C$36))*($C$37/(SUM($C$36:$C$39)-$C$36-$C$39))+($C$38/SUM($C$36:$C$39))*($C$36/(SUM($C$36:$C$39)-$C$38))*($C$37/(SUM($C$36:$C$39)-$C$38-$C$36))+($C$38/SUM($C$36:$C$39))*($C$39/(SUM($C$36:$C$39)-$C$38))*($C$37/(SUM($C$36:$C$39)-$C$38-$C$39))+($C$39/SUM($C$36:$C$39))*($C$36/(SUM($C$36:$C$39)-$C$39))*($C$37/(SUM($C$36:$C$39)-$C$39-$C$36))+($C$39/SUM($C$36:$C$39))*($C$38/(SUM($C$36:$C$39)-$C$39))*($C$37/(SUM($C$36:$C$39)-$C$39-$C$38)) -> 0.25119208 | G37: =($C$36/SUM($C$36:$C$39))*($C$38/(SUM($C$36:$C$39)-$C$36))*($C$39/(SUM($C$36:$C$39)-$C$36-$C$38))*($C$37/(SUM($C$36:$C$39)-$C$36-$C$38-$C$39))+($C$36/SUM($C$36:$C$39))*($C$39/(SUM($C$36:$C$39)-$C$36))*($C$38/(SUM($C$36:$C$39)-$C$36-$C$39))*($C$37/(SUM($C$36:$C$39)-$C$36-$C$39-$C$38))+($C$38/SUM($C$36:$C$39))*($C$36/(SUM($C$36:$C$39)-$C$38))*($C$39/(SUM($C$36:$C$39)-$C$38-$C$36))*($C$37/(SUM($C$36:$C$39)-$C$38-$C$36-$C$39))+($C$38/SUM($C$36:$C$39))*($C$39/(SUM($C$36:$C$39)-$C$38))*($C$36/(SUM($C$36:$C$39)-$C$38-$C$39))*($C$37/(SUM($C$36:$C$39)-$C$38-$C$39-$C$36))+($C$39/SUM($C$36:$C$39))*($C$36/(SUM($C$36:$C$39)-$C$39))*($C$38/(SUM($C$36:$C$39)-$C$39-$C$36))*($C$37/(SUM($C$36:$C$39)-$C$39-$C$36-$C$38))+($C$39/SUM($C$36:$C$39))*($C$38/(SUM($C$36:$C$39)-$C$39))*($C$36/(SUM($C$36:$C$39)-$C$39-$C$38))*($C$37/(SUM($C$36:$C$39)-$C$39-$C$38-$C$36)) -> 0.23223872 | H37: =MIN(1,(IF(AND(0>=$D$34,0<=$F$34),0,0)+IF(AND(1>=$D$34,1<=$F$34),D37,0)+IF(AND(2>=$D$34,2<=$F$34),D37+E37,0)+IF(AND(3>=$D$34,3<=$F$34),D37+E37+F37,0)+IF(AND(4>=$D$34,4<=$F$34),D37+E37+F37+G37,0)+IF(AND(5>=$D$34,5<=$F$34),D37+E37+F37+G37,0)+IF(AND(6>=$D$34,6<=$F$34),D37+E37+F37+G37,0)+IF(AND(7>=$D$34,7<=$F$34),D37+E37+F37+G37,0)+IF(AND(8>=$D$34,8<=$F$34),D37+E37+F37+G37,0))/($F$34-$D$34+1)) -> 0.64216524 | I37: Meditation (30 ash) | K37: shrine_offerings | L37: scavenge · perception 50 XP · 3.2s
A38: shrine_pillars | B38: Carved pillars | C38: =Encounters!F64 -> 6 | D38: =$C$38/SUM($C$36:$C$39) -> 0.22222222 | E38: =($C$36/SUM($C$36:$C$39))*($C$38/(SUM($C$36:$C$39)-$C$36))+($C$37/SUM($C$36:$C$39))*($C$38/(SUM($C$36:$C$39)-$C$37))+($C$39/SUM($C$36:$C$39))*($C$38/(SUM($C$36:$C$39)-$C$39)) -> 0.23483709 | F38: =($C$36/SUM($C$36:$C$39))*($C$37/(SUM($C$36:$C$39)-$C$36))*($C$38/(SUM($C$36:$C$39)-$C$36-$C$37))+($C$36/SUM($C$36:$C$39))*($C$39/(SUM($C$36:$C$39)-$C$36))*($C$38/(SUM($C$36:$C$39)-$C$36-$C$39))+($C$37/SUM($C$36:$C$39))*($C$36/(SUM($C$36:$C$39)-$C$37))*($C$38/(SUM($C$36:$C$39)-$C$37-$C$36))+($C$37/SUM($C$36:$C$39))*($C$39/(SUM($C$36:$C$39)-$C$37))*($C$38/(SUM($C$36:$C$39)-$C$37-$C$39))+($C$39/SUM($C$36:$C$39))*($C$36/(SUM($C$36:$C$39)-$C$39))*($C$38/(SUM($C$36:$C$39)-$C$39-$C$36))+($C$39/SUM($C$36:$C$39))*($C$37/(SUM($C$36:$C$39)-$C$39))*($C$38/(SUM($C$36:$C$39)-$C$39-$C$37)) -> 0.25376904 | G38: =($C$36/SUM($C$36:$C$39))*($C$37/(SUM($C$36:$C$39)-$C$36))*($C$39/(SUM($C$36:$C$39)-$C$36-$C$37))*($C$38/(SUM($C$36:$C$39)-$C$36-$C$37-$C$39))+($C$36/SUM($C$36:$C$39))*($C$39/(SUM($C$36:$C$39)-$C$36))*($C$37/(SUM($C$36:$C$39)-$C$36-$C$39))*($C$38/(SUM($C$36:$C$39)-$C$36-$C$39-$C$37))+($C$37/SUM($C$36:$C$39))*($C$36/(SUM($C$36:$C$39)-$C$37))*($C$39/(SUM($C$36:$C$39)-$C$37-$C$36))*($C$38/(SUM($C$36:$C$39)-$C$37-$C$36-$C$39))+($C$37/SUM($C$36:$C$39))*($C$39/(SUM($C$36:$C$39)-$C$37))*($C$36/(SUM($C$36:$C$39)-$C$37-$C$39))*($C$38/(SUM($C$36:$C$39)-$C$37-$C$39-$C$36))+($C$39/SUM($C$36:$C$39))*($C$36/(SUM($C$36:$C$39)-$C$39))*($C$37/(SUM($C$36:$C$39)-$C$39-$C$36))*($C$38/(SUM($C$36:$C$39)-$C$39-$C$36-$C$37))+($C$39/SUM($C$36:$C$39))*($C$37/(SUM($C$36:$C$39)-$C$39))*($C$36/(SUM($C$36:$C$39)-$C$39-$C$37))*($C$38/(SUM($C$36:$C$39)-$C$39-$C$37-$C$36)) -> 0.28917165 | H38: =MIN(1,(IF(AND(0>=$D$34,0<=$F$34),0,0)+IF(AND(1>=$D$34,1<=$F$34),D38,0)+IF(AND(2>=$D$34,2<=$F$34),D38+E38,0)+IF(AND(3>=$D$34,3<=$F$34),D38+E38+F38,0)+IF(AND(4>=$D$34,4<=$F$34),D38+E38+F38+G38,0)+IF(AND(5>=$D$34,5<=$F$34),D38+E38+F38+G38,0)+IF(AND(6>=$D$34,6<=$F$34),D38+E38+F38+G38,0)+IF(AND(7>=$D$34,7<=$F$34),D38+E38+F38+G38,0)+IF(AND(8>=$D$34,8<=$F$34),D38+E38+F38+G38,0))/($F$34-$D$34+1)) -> 0.58394383 | I38: Meditation (30 ash) | L38: study · intelligence 85 XP · 4.4s
